Workbook

Sheet Instructions
A1: Amazon Ads Data Clean up & Diagnosis
A2: Brand: Auralis Naturals
A3: Scenario | B3: This data is from skincare seller - a one-month Sponsored Products 'Search Term Report' (about 3,000 rows, 26 columns). The export is messy. You need to identify where money is being wasted, what is working, and what to change first.
A4: No Amazon knowledge needed | B4: Everything you need is defined in the Glossary below.
A6: Effort | B6: About 2 hours. You will be asked to walk us through it and explain working. You may use online resources for reference and help. Do not upload the sheet to AI and ask it to solve. AI work will be easily identifiable and will result in cancellation of your candidature.
A7: Tool | B7: Microsoft Excel. Classic functions are enough (VLOOKUP/INDEX-MATCH, SUMIFS, COUNTIFS, IF, IFERROR, TRIM, LOWER, pivot tables). You may use any of them.
A9: THE TASKS (suggested time in brackets)
A10: A. Clean the data (35 min) | B10: Copy Search_Term_Report to a new sheet called 'Clean_Data' and fix the data there. Record every problem you find in 'Cleaning_Log': what the issue is, where it is, roughly how many rows, and what you did. Do not silently delete anything. If you are unsure whether to keep or remove something, decide, and write down why.
A11: B. Add calculated columns (20 min) | B11: In Clean_Data, add formula columns (not pasted values): Week No., Selling Price, Break-even ACOS (look up from Product_Master), your own CTR, CPC, ACOS, ROAS and CVR (do not trust the pre-filled ones), Profit after ads, and Row Status. Row Status: 'Profitable' if Sales > 0 and ACOS < Break-even ACOS; 'Losing' if Sales > 0 and ACOS ≥ Break-even ACOS; 'No Sales' if Sales = 0 and Spend > 0; 'No Spend' if Spend = 0; 'Cost missing' if the SKU cannot be found in Product_Master.
A12: C. Analyse (35 min) | B12: On a sheet called 'Analysis' (pivot tables are fine), show: C1. Campaign summary: Spend, Sales, Orders, ACOS, ROAS and Profit after ads per campaign. C2. The same measures by Match Type and by Placement. C3. Top 10 search terms by Spend that have ZERO orders (treat the same term typed in different cases as one term). C4. Top 10 search terms by Profit after ads. C5. Week 1 to Week 4 trend of Spend, Sales, Orders, ACOS and CVR, with one chart. C6. (Stretch) Search terms that appear in more than one campaign, with their combined Spend and Sales.
A13: D. Action_List (20 min) | B13: Apply the four rules in Seller_Notes and list every recommended action on a sheet called 'Action_List' using the headers provided in that sheet.
A14: E. Summary for the seller (10 min) | B14: On a sheet called 'Summary', write a note of no more than 150 words to a non-technical seller: answer their question about the end of the month, say what is going wrong, what you would do first, and anything you were unsure about.
A15: Optional | B15: A one-page dashboard sheet. It will not earn a pass on its own; do it only if you finish early.
A17: HOW YOU WILL BE JUDGED
A18: What we look for | B18: Care with the data (did you find and handle the problems?), correct formulas and method, correct analysis, sensible recommendations that follow the rules, a clear summary, and following instructions (sheet names, file name, deadline). Neatness matters. Being honest about what you were unsure of scores higher than guessing.
B19: This job assumes you do not know anything about Amazon Ads. So do not worry about getting everything 100% right, it’s the approach that matters.
A20: GLOSSARY
A21: Search term | B21: What the shopper actually typed into Amazon search box before seeing/clicking the ad.
A22: Impressions | B22: Number of times the ad was shown. Typically Amazon does not charge on Impressions.
A23: Clicks | B23: Number of times shoppers clicked the ad. Amazon charges every time someone clicks on your ad.
A24: CTR (click-through rate) | B24: Clicks ÷ Impressions - Higher CTR implies that consumers found your ad to be relevant.
A25: CPC (cost per click) | B25: Spend ÷ Clicks.
A26: Spend | B26: What the seller paid Amazon for the clicks (₹).
A27: Sales (7-day) | B27: Sales (₹) that Amazon credits to the ad within 7 days of the click.
A28: Orders / Units | B28: Number of orders / number of items sold. One order can contain several units.
A29: CVR (conversion rate) | B29: Orders ÷ Clicks.
A30: ACOS | B30: Spend ÷ Sales. Lower is better. Example: Spend ₹300, Sales ₹1,000 gives ACOS 30%.
A31: ROAS | B31: Sales ÷ Spend (the inverse of ACOS).
A32: Break-even ACOS | B32: (Selling Price - Product Cost - Amazon Fees) ÷ Selling Price. If a product's ACOS is above this, every ad sale loses money.
... A36: Negate / negative keyword | B36: Tell Amazon to stop showing the ad for a search term.
A38: FILE MAP
A39: Search_Term_Report | B39: Main data. One row per date, campaign, ad group and search term (Sep 2026).
A40: Product_Master | B40: Selling price, cost and fees per SKU, plus stock status.
A41: Campaign_List | B41: All campaigns, budgets and status.
A42: Seller_Notes | B42: The seller's message, rules for Task D, competitor names.
A43: Cleaning_Log, Action_List | B43: Templates are included. Replace the example row (shaded) with your own entries.
A45: ASIN | B45: Amazon identification of a product - Aadhar number of a product on Amazon
A46: SKU | B46: Stock Keeping Unit - An ASIN may be mapped to multiple ASIN, one SKU can be mapped to only one ASIN.
A47: Ad Group | B47: An Ad Group containst ASINs (products) that are being advertised, and targets (keywords etc) on which the ad is to be shown, along with bid (price we are ready to pay for a click for that particular target).
A48: Campaign | B48: Cluster of Ad Groups

Sheet Search_Term_Report
A1: Date | B1: Campaign Name | C1: Portfolio | D1: Campaign Status | E1: Ad Group | F1: Ad Format | G1: Targeting | H1: Match Type | I1: Customer Search Term | J1: Product SKU | K1: Placement | L1: Impressions | M1: Clicks | N1: CTR | O1: CPC (₹) | P1: Spend (₹) | Q1: 7 Day Total Sales (₹) | R1: 7 Day Total Orders | S1: 7 Day Total Units | T1: ACOS | U1: ROAS | V1: CVR | W1: Bid (₹) | X1: Currency | Y1: Region | Z1: Notes
A2: 46266 | B2: SP | Auto | Face Care | C2: Face Care | D2: Enabled | E2: AG | Vitamin C Serum | F2: Sponsored Products | G2: close-match | H2: Auto | I2: best face serum vitamin c | J2: SKN-001 | K2: Top of Search | L2: 125 | M2: 4 | N2: 0.032 | O2: 15.54 | P2: 62.16 | Q2: 0 | R2: 0 | S2: 0 | U2: 0 | V2: 0 | W2: 17.5 | X2: INR | Y2: India
A3: 46266 | B3: SP | Auto | Face Care | C3: Face Care | D3: Enabled | E3: AG | Niacinamide Serum | F3: Sponsored Products | G3: loose-match | H3: Auto | I3: niacinamide serum with vitamin e | J3: SKN-002 | K3: Top of Search | L3: 300 | M3: 4 | N3: 0.013333333 | O3: 16.5 | P3: 66 | Q3: 0 | R3: 0 | S3: 0 | U3: 0 | V3: 0 | W3: 16.5 | X3: INR | Y3: India
A4: 01-Sep-2026 | B4: SP | Auto | Face Care | C4: Face Care | D4: Enabled | E4: AG | Niacinamide Serum | F4: Sponsored Products | G4: close-match | H4: Auto | I4: organic niacinamide 10% serum | J4: SKN-002 | K4: Product Pages | L4: 201 | M4: 5 | N4: 0.024875622 | O4: 6.14 | P4: 30.7 | Q4: 0 | R4: 0 | S4: 0 | U4: 0 | V4: 0 | W4: 10.5 | X4: INR | Y4: India
A5: 46266 | B5: SP | Auto | Face Care | C5: Face Care | D5: Enabled | E5: AG | Niacinamide Serum | F5: Sponsored Products | G5: loose-match | H5: Auto | I5: niacinamide 10% serum | J5: SKN-002 | K5: Rest of Search | L5: 808 | M5: 4 | N5: 0.004950495 | O5: 6.82 | P5: 27.28 | Q5: 0 | R5: 0 | S5: 0 | U5: 0 | V5: 0 | W5: 10 | X5: INR | Y5: India
A6: 46266 | B6: SP | Auto | Face Care | C6: Face Care | D6: Enabled | E6: AG | Gel Moisturizer | F6: Sponsored Products | G6: loose-match | H6: Auto | I6: organic gel moisturizer | J6: SKN-005 | K6: Product Pages | L6: 216 | M6: 0 | N6: 0 | P6: 0 | Q6: 0 | R6: 0 | S6: 0 | W6: 12 | X6: INR | Y6: India
A7: 01.09.2026 | B7: SP | Auto | Face Care | C7: Face Care | D7: Enabled | E7: AG | Gel Moisturizer | F7: Sponsored Products | G7: close-match | H7: Auto | I7: face moisturizer | J7: SKN-005 | K7: Rest of Search | L7: 1431 | M7: 17 | N7: 0.011879804 | O7: 6 | P7: 102 | Q7: 399 | R7: 1 | S7: 1 | T7: 0.2556 | U7: 3.91 | V7: 0.0588 | W7: 10.5 | X7: INR | Y7: India
A8: 46266 | B8: SP | Auto | Face Care | C8: Face Care | D8: Enabled | E8: AG | Gel Moisturizer | F8: Sponsored Products | G8: close-match | H8: Auto | I8: gel moisturizer | J8: SKN-005 | K8: Top of Search | L8: 1,449 | M8: 22 | N8: 0.015182885 | O8: 11.5 | P8: 253 | Q8: 1197 | R8: 3 | S8: 3 | T8: 0.2114 | U8: 4.73 | V8: 0.1364 | W8: 12 | X8: INR | Y8: India
A9: 46266 | B9: SP | Auto | Face Care | C9: Face Care | D9: Enabled | E9: AG | Sunscreen Spf 50 | F9: Sponsored Products | G9: close-match | H9: Auto | I9: sunscreen spf 50 | J9: SKN-006 | K9: Product Pages | L9: 2603 | M9: 14 | N9: 0.0053784095 | O9: 7.67 | P9: 107.38 | Q9: 0 | R9: 0 | S9: 0 | U9: 0 | V9: 0 | W9: 12 | X9: INR | Y9: India
A10: 46266 | B10: SP | Auto | Face Care | C10: Face Care | D10: Enabled | E10: AG | Rose Water Toner | F10: Sponsored Products | G10: close-match | H10: Auto | I10: rose water toner | J10: SKN-010 | K10: Top of Search | L10: 993 | M10: 3 | N10: 0.003021148 | O10: 7.49 | P10: 22.47 | Q10: 0 | R10: 0 | S10: 0 | U10: 0 | V10: 0 | W10: 8 | X10: INR | Y10: India
A11: 01-Sep-2026 | B11: SP | Auto | Face Care | C11: Face Care | D11: Enabled | E11: AG | Rose Water Toner | F11: Sponsored Products | G11: complements | H11: Auto | I11: face cream for dogs | J11: SKN-010 | K11: Product Pages | L11: 233 | M11: 2 | N11: 0.008583691 | O11: 2.95 | P11: 5.9 | Q11: 0 | R11: 0 | S11: 0 | U11: 0 | V11: 0 | W11: 5.5 | X11: INR | Y11: India
A12: 46266 | B12: SP | Auto | Face Care | C12: Face Care | D12: Enabled | E12: AG | Rose Water Toner | F12: Sponsored Products | G12: close-match | H12: Auto | I12: face toner price | J12: SKN-010 | K12: Top of Search | L12: 247 | M12: 1 | N12: 0.004048583 | O12: 6 | P12: 6 | Q12: 0 | R12: 0 | S12: 0 | U12: 0 | V12: 0 | W12: 6 | X12: INR | Y12: India
A13: 46266 | B13: SP | Auto | Body & Hair | C13: Body & Hair | D13: Enabled | E13: AG | Body Lotion | F13: Sponsored Products | G13: close-match | H13: Auto | I13: body lotion for dry skin | J13: SKN-017 | K13: Rest of Search | L13: 1128 | M13: 5 | N13: 0.0044326241 | O13: 7.2 | P13: 36 | Q13: 0 | R13: 0 | S13: 0 | U13: 0 | V13: 0 | W13: 12 | X13: INR | Y13: India | Z13: seller wants to monitor
A14: 46266 | B14: SP | Auto | Body & Hair | C14: Body & Hair | D14: Enabled | E14: AG | Body Lotion | F14: Sponsored Products | G14: substitutes | H14: Auto | I14: veluna shea body lotion | J14: SKN-017 | K14: Top of Search | L14: 115 | M14: 1 | N14: 0.0086956522 | O14: 14 | P14: 14 | Q14: 0 | R14: 0 | S14: 0 | U14: 0 | V14: 0 | W14: 14 | X14: INR | Y14: India
A15: 46287 | B15: SP | Manual | Masks & Gels | Broad | C15: Face Care | D15: Paused | E15: AG | Clay Face Mask | F15: Sponsored Products | G15: multani mitti face pack | H15: broad | I15: face cream for dogs | J15: SKN-012 | K15: Top of Search | L15: 176 | M15: 2 | N15: 0.0114 | O15: 13.87 | P15: 27.74 | Q15: 0 | R15: 0 | S15: 0 | U15: 0 | V15: 0 | W15: 7.5 | X15: INR | Y15: India
A16: 01-Sep-2026 | B16: SP | Auto | Body & Hair | C16: Body & Hair | D16: Enabled | E16: AG | Body Lotion | F16: Sponsored Products | G16: loose-match | H16: Auto | I16: baby lotion | J16: SKN-017 | K16: Top of Search | L16: 914 | M16: 15 | N16: 0.016411379 | O16: 9 | P16: 135 | Q16: 0 | R16: 0 | S16: 0 | U16: 0 | V16: 0 | W16: 9 | X16: INR | Y16: India
A17: 46266 | B17: SP | Auto | Body & Hair | C17: Body & Hair | D17: Enabled | E17: AG | Body Wash | F17: Sponsored Products | G17: close-match | H17: Auto | I17: body wash under 300 | J17: SKN-018 | K17: Product Pages | L17: 172 | M17: 1 | N17: 0.0058139535 | O17: 4.72 | P17: 4.72 | Q17: 0 | R17: 0 | S17: 0 | U17: 0 | V17: 0 | W17: 8.5 | X17: INR | Y17: India
A18: 46266 | B18: SP | Auto | Body & Hair | C18: Body & Hair | D18: Enabled | E18: AG | Body Wash | F18: Sponsored Products | G18: close-match | H18: Auto | I18: body wash | J18: SKN-018 | K18: Product Pages | L18: 1183 | M18: 7 | N18: 0.0059171598 | O18: 4.38 | P18: 30.66 | Q18: 0 | R18: 0 | S18: 0 | U18: 0 | V18: 0 | W18: 8.5 | X18: INR | Y18: India
A19: 46266 | B19: SP | Auto | Body & Hair | C19: Body & Hair | D19: Enabled | E19: AG | Body Wash | F19: Sponsored Products | G19: close-match | H19: Auto | I19: body wash for women under 300 | J19: SKN-018 | K19: Top of Search | L19: 772 | M19: 12 | N19: 0.015544041 | O19: 7.5 | P19: 90 | Q19: 0 | R19: 0 | S19: 0 | U19: 0 | V19: 0 | W19: 7.5 | X19: INR | Y19: India
A20: 46266 | B20: SP | Auto | Body & Hair | C20: Body & Hair | D20: Enabled | E20: AG | Body Wash | F20: Sponsored Products | G20: loose-match | H20: Auto | I20: body wash for women paraben free | J20: SKN-018 | K20: Rest of Search | L20: 927 | M20: 4 | N20: 0.0043149946 | O20: 6.04 | P20: 24.16 | Q20: 0 | R20: 0 | S20: 0 | U20: 0 | V20: 0 | W20: 8.5 | X20: INR | Y20: India
A21: 46266 | B21: SP | Auto | Body & Hair | C21: Body & Hair | D21: Enabled | E21: AG | Body Wash | F21: Sponsored Products | G21: complements | H21: Auto | I21: baby lotion | J21: SKN-018 | K21: Top of Search | L21: 150 | M21: 0 | N21: 0 | P21: 0 | Q21: 0 | R21: 0 | S21: 0 | W21: 8 | X21: INR | Y21: India
A22: 46266 | B22: SP | Auto | Body & Hair | C22: Body & Hair | D22: Enabled | E22: AG | Onion Hair Oil | F22: Sponsored Products | G22: loose-match | H22: Auto | I22: onion hair oil | J22: SKN-021 | K22: Top of Search | L22: 405 | M22: 4 | N22: 0.0098765432 | O22: 9.5 | P22: ₹38.00 | Q22: 798 | R22: 1 | S22: 2 | T22: 0.0476 | U22: 21 | V22: 0.25 | W22: 9.5 | X22: INR | Y22: India
A23: 46266 | B23: SP | Auto | Body & Hair | C23: Body & Hair | D23: Enabled | E23: AG | Onion Hair Oil | F23: Sponsored Products | G23: close-match | H23: Auto | I23: hair oil for hair growth | J23: SKN-021 | K23: Rest of Search | L23: 1645 | M23: 13 | N23: 0.0079027356 | O23: 6.16 | P23: 80.08 | Q23: 798 | R23: 2 | S23: 2 | T23: 0.1004 | U23: 9.97 | V23: 0.1538 | W23: 7.5 | X23: INR | Y23: India
A24: 46266 | B24: SP | Auto | Body & Hair | C24: Body & Hair | D24: Enabled | E24: AG | Onion Hair Oil | F24: Sponsored Products | G24: close-match | H24: Auto | I24: hair oil for hair growth for oily scalp | J24: SKN-021 | K24: Rest of Search | L24: 415 | M24: 3 | N24: 0.0072289157 | O24: 6.16 | P24: 18.48 | Q24: 399 | R24: 1 | S24: 1 | T24: 0.0463 | U24: 21.59 | V24: 0.3333 | W24: 11 | X24: INR | Y24: India
A25: 46266 | B25: SP | Auto | Body & Hair | C25: Body & Hair | D25: Enabled | E25: AG | Onion Hair Oil | F25: Sponsored Products | G25: loose-match | H25: Auto | I25: hair dryer | J25: SKN-021 | K25: Product Pages | L25: 569 | M25: 4 | N25: 0.007029877 | O25: 6.74 | P25: 26.96 | Q25: 0 | R25: 0 | S25: 0 | U25: 0 | V25: 0 | W25: 12.5 | X25: INR | Y25: India
A26: 46266 | B26: SP | Auto | Body & Hair | C26: Body & Hair | D26: Enabled | E26: AG | Anti Dandruff Shampoo | F26: Sponsored Products | G26: loose-match | H26: Auto | I26: anti dandruff shampoo paraben free | J26: SKN-022 | K26: Rest of Search | L26: 798 | M26: 6 | N26: 0.007518797 | O26: 5.18 | P26: 31.08 | Q26: 429 | R26: 1 | S26: 1 | T26: 0.0724 | U26: 13.8 | V26: 0.1667 | W26: 9 | X26: INR | Y26: India
A27: 01-Sep-2026 | B27: SP | Manual | Face Serums | Exact | C27: Face Care | D27: Enabled | E27: AG | Vitamin C Serum | F27: Sponsored Products | G27: face serum vitamin c pack of 2 | H27: Exact match | I27: face serum vitamin c pack of 2 | J27: SKN-001 | K27: Rest of Search | L27: 585 | M27: 2 | N27: 0.0034188034 | O27: 12.18 | P27: 24.36 | Q27: 599 | R27: 1 | S27: 1 | T27: 0.0407 | U27: 24.59 | V27: 0.5 | W27: 18.5 | X27: INR | Y27: India
A28: 46266 | B28: SP | Manual | Face Serums | Exact | C28: Face Care | D28: Enabled | E28: AG | Vitamin C Serum | F28: Sponsored Products | G28: vit c face serum | H28: Exact | I28: vit c face serum | J28: SKN-001 | K28: Top of Search | L28: 349 | M28: 2 | N28: 0.005730659 | O28: 10.97 | P28: 21.94 | Q28: 0 | R28: 0 | S28: 0 | U28: 0 | V28: 0 | W28: 14 | X28: INR | Y28: India
A29: 46266 | B29: SP | Manual | Face Serums | Exact | C29: Face Care | D29: Enabled | E29: AG | Vitamin C Serum | F29: Sponsored Products | G29: face serum vitamin c | H29: Exact | I29: face serum vitamin c | J29: SKN-001 | K29: Product Pages | L29: 895 | M29: 10 | N29: 0.011173184 | O29: 10.64 | P29: 106.4 | Q29: 0 | R29: 0 | S29: 0 | U29: 0 | V29: 0 | W29: 15.5 | X29: INR | Y29: India
A30: 46266 | B30: SP | Manual | Face Serums | Exact | C30: Face Care | D30: Enabled | E30: AG | Niacinamide Serum | F30: Sponsored Products | G30: niacinamide 10% serum under 300 | H30: Exact | I30: niacinamide 10% serum under 300 | J30: SKN-002 | K30: Product Pages | L30: 560 | M30: 6 | N30: 0.010714286 | O30: 8.03 | P30: 48.18 | Q30: 549 | R30: 1 | S30: 1 | T30: 0.0878 | U30: 11.39 | V30: 0.1667 | W30: 13 | X30: INR | Y30: India
A31: 46266 | B31: SP | Manual | Face Serums | Exact | C31: Face Care | D31: Enabled | E31: AG | Niacinamide Serum | F31: Sponsored Products | G31: niacinamide 10% serum | H31: Exact | I31: niacinamide 10% serum | J31: SKN-002 | K31: Rest of Search | L31: 1024 | M31: 2 | N31: 0.001953125 | O31: 10.52 | P31: 21.04 | Q31: 0 | R31: 0 | S31: 0 | U31: 0 | V31: 0 | W31: 15 | X31: INR | Y31: India
A32: 46266 | B32: SP | Manual | Face Serums | Exact | C32: Face Care | D32: Enabled | E32: AG | Niacinamide Serum | F32: Sponsored Products | G32: niacinamide serum | H32: Exact | I32: niacinamide serum | J32: SKN-002 | K32: Product Pages | L32: 762 | M32: 9 | N32: 0.011811024 | O32: 11.69 | P32: 105.21 | Q32: 0 | R32: 0 | S32: 0 | U32: 0 | V32: 0 | W32: 15 | X32: INR | Y32: India
A33: 46266 | B33: SP | Manual | Face Serums | Exact | C33: Face Care | D33: Enabled | E33: AG | Hyaluronic Acid Serum | F33: Sponsored Products | G33: hyaluronic acid serum for dry skin | H33: exact | I33: hyaluronic acid serum for dry skin | J33: SKN-003 | K33: Top of Search | L33: 100 | M33: 1 | N33: 0.01 | O33: 24 | P33: 24 | Q33: 0 | R33: 0 | S33: 0 | U33: 0 | V33: 0 | W33: 24 | X33: INR | Y33: India
A34: 46266 | B34: SP | Manual | Face Serums | Exact | C34: Face Care | D34: Enabled | E34: AG | Hyaluronic Acid Serum | F34: Sponsored Products | G34: hyaluronic serum | H34: Exact | I34: hyaluronic serum | J34: SKN-003 | K34: Product Pages | L34: 919 | M34: 11 | N34: 0.011969532 | O34: 17.49 | P34: ₹192.39 | Q34: 649 | R34: 1 | S34: 1 | T34: 0.2964 | U34: 3.37 | V34: 0.0909 | W34: 25 | X34: INR | Y34: India
A35: 46266 | B35: SP | Manual | Face Serums | Exact | C35: Face Care | D35: Enabled | E35: AG | Retinol Night Cream | F35: Sponsored Products | G35: night cream for face | H35: Exact | I35: night cream for face | J35: SKN-004 | K35: Product Pages | L35: 486 | M35: 0 | N35: 0 | P35: 0 | Q35: 0 | R35: 0 | S35: 0 | W35: 23.5 | X35: INR | Y35: India
A36: 46266 | B36: SP | Manual | Face Serums | Broad | C36: Face Care | D36: Enabled | E36: AG | Niacinamide Serum | F36: Sponsored Products | G36: niacinamide 10% serum | H36: Broad | I36: pureroots niacinamide 10% serum | J36: SKN-002 | K36: Top of Search | L36: 345 | M36: 1 | N36: 0.0028985507 | O36: 10.5 | P36: 10.5 | Q36: 0 | R36: 0 | S36: 0 | U36: 0 | V36: 0 | W36: 10.5 | X36: INR | Y36: India
A37: 46266 | B37: SP | Manual | Face Serums | Broad | C37: Face Care | D37: Enabled | E37: AG | Niacinamide Serum | F37: Sponsored Products | G37: niacinamide 10% serum | H37: Broad | I37: BEST NIACINAMIDE 10% SERUM | J37: SKN-002 | K37: Rest of Search | L37: 357 | M37: 1 | N37: 0.0028011204 | O37: 7.68 | P37: 7.68 | Q37: 0 | R37: 0 | S37: 0 | U37: 0 | V37: 0 | W37: 12.5 | X37: Rs. | Y37: India
A38: 46266 | B38: SP | Manual | Face Serums | Broad | C38: Face Care | D38: Enabled | E38: AG | Hyaluronic Acid Serum | F38: Sponsored Products | G38: hyaluronic serum | H38: Broad | I38: hyaluronic serum | J38: SKN-003 | K38: Rest of Search | L38: 1412 | M38: 14 | N38: 0.0099150142 | O38: 10.55 | P38: 147.7 | Q38: 0 | R38: 0 | S38: 0 | U38: 0 | V38: 0 | W38: 14 | X38: INR | Y38: India
A39: 46266 | B39: SP | Manual | Face Serums | Broad | C39: Face Care | D39: Enabled | E39: AG | Hyaluronic Acid Serum | F39: Sponsored Products | G39: hyaluronic serum | H39: Broad | I39: face serum hyaluronic for daily use | J39: SKN-003 | K39: Top of Search | L39: 174 | M39: 4 | N39: 0.022988506 | O39: 14.5 | P39: 58 | Q39: 649 | R39: 1 | S39: 1 | T39: 0.0894 | U39: 11.19 | V39: 0.25 | W39: 14.5 | X39: INR | Y39: India
A40: 46266 | B40: SP | Manual | Face Serums | Broad | C40: Face Care | D40: Enabled | E40: AG | Hyaluronic Acid Serum | F40: Sponsored Products | G40: hyaluronic acid serum | H40: Broad | I40: face serum hyaluronic pack of 2 | J40: SKN-003 | K40: Product Pages | L40: 239 | M40: 1 | N40: 0.0041841004 | O40: 6.67 | P40: 6.67 | Q40: 0 | R40: 0 | S40: 0 | U40: 0 | V40: 0 | W40: 12 | X40: INR | Y40: India
...

Sheet Product_Master
A1: Product_Master
A2: Selling price, cost and Amazon fees are in ₹ per unit. Net margin before ads = Price - Cost - Fees.
A4: SKU | B4: ASIN | C4: Product Name | D4: Sub-Category | E4: Selling Price (₹) | F4: Product Cost (₹) | G4: Amazon Fees (₹) | H4: Stock Status | I4: Rating | J4: Reviews
A5: SKN-001 | B5: B0F29326ML | C5: Auralis Vitamin C Face Serum 30ml | D5: Face Serum | E5: 599 | F5: 216 | G5: 144 | H5: In Stock | I5: 4.5 | J5: 2849
A6: SKN-002 | B6: B0F64LG2TJ | C6: Auralis Niacinamide 10% Face Serum 30ml | D6: Face Serum | E6: 549 | F6: 192 | G6: 139 | H6: In Stock | I6: 4 | J6: 1762
A7: SKN-003 | B7: B0FF8CZ2KA | C7: Auralis Hyaluronic Acid Face Serum 30ml | D7: Face Serum | E7: 649 | F7: 234 | G7: 148 | H7: In Stock | I7: 4.5 | J7: 1122
A8: SKN-004 | B8: B0F7EDCMPB | C8: Auralis Retinol Night Cream 50g | D8: Night Cream | E8: 799 | F8: 272 | G8: 162 | H8: In Stock | I8: 4.1 | J8: 4750
A9: SKN-005 | B9: B0F3U2M7OS | C9: Auralis Oil-Free Gel Moisturiser 100g | D9: Moisturiser | E9: 399 | F9: 148 | G9: 126 | H9: In Stock | I9: 4.6 | J9: 2128
A10: SKN-006 | B10: B0F5AF3R09 | C10: Auralis Sunscreen SPF 50 PA++++ 50g | D10: Sunscreen | E10: 449 | F10: 162 | G10: 130 | H10: In Stock | I10: 4 | J10: 4281
A11: SKN-007 | B11: B0FFQUO6SB | C11: Auralis Tinted Sunscreen SPF 40 50g | D11: Sunscreen | E11: 549 | F11: 203 | G11: 139 | H11: In Stock | I11: 3.9 | J11: 2473
A12: SKN-008 | B12: B0FEGZGSYE | C12: Auralis Foaming Face Wash 150ml | D12: Face Wash | E12: 299 | F12: 114 | G12: 107 | H12: In Stock | I12: 3.9 | J12: 4252
A13: SKN-009 | B13: B0FBANND4Y | C13: Auralis Salicylic Acid Face Wash 100ml | D13: Face Wash | E13: 279 | F13: 106 | G13: 105 | H13: In Stock | I13: 4 | J13: 1746
A14: SKN-010 | B14: B0FZ0EMRVF | C14: Auralis Rose Water Toner 200ml | D14: Toner | E14: 249 | F14: 100 | G14: 102 | H14: In Stock | I14: 4.3 | J14: 3363
A15: SKN-011 | B15: B0FTVA0HIP | C15: Auralis Under Eye Cream 15g | D15: Eye Care | E15: 499 | F15: 180 | G15: 125 | H15: In Stock | I15: 4 | J15: 2813
A16: SKN-012 | B16: B0FGAD35L9 | C16: Auralis Clay Face Mask 100g | D16: Face Mask | E16: 379 | F16: 140 | G16: 114 | H16: In Stock | I16: 4 | J16: 4693
... A29: SKN-026 | B29: B0FQ61J0AC | C29: Auralis Bath Salt Scrub 250g | D29: Body Care | E29: 379 | F29: 140 | G29: 90 | H29: Discontinued | I29: 4 | J29: 310

Sheet Campaign_List
A1: Campaign_List
A2: All Sponsored Products campaigns in the account.
A4: Campaign Name | B4: Targeting Type | C4: Portfolio | D4: Daily Budget (₹) | E4: Status | F4: Paused On | G4: Objective
A5: SP | Auto | Face Care | B5: Auto | C5: Face Care | D5: 950 | E5: Enabled | G5: Discover new search terms
A6: SP | Auto | Body & Hair | B6: Auto | C6: Body & Hair | D6: 650 | E6: Enabled | G6: Discover new search terms
A7: SP | Manual | Face Serums | Exact | B7: Manual | C7: Face Care | D7: 1550 | E7: Enabled | G7: Scale proven terms
A8: SP | Manual | Face Serums | Broad | B8: Manual | C8: Face Care | D8: 600 | E8: Enabled | G8: Explore variations
A9: SP | Manual | Sunscreen | Phrase | B9: Manual | C9: Face Care | D9: 400 | E9: Enabled | G9: Explore variations
A10: SP | Manual | Skincare Essentials | Broad | B10: Manual | C10: Face Care | D10: 550 | E10: Enabled | G10: Explore variations
A11: SP | Manual | Hair Care | Phrase | B11: Manual | C11: Body & Hair | D11: 500 | E11: Enabled | G11: Explore variations
A12: SP | Manual | Body Care | Exact | B12: Manual | C12: Body & Hair | D12: 800 | E12: Enabled | G12: Scale proven terms
A13: SP | Product Targeting | Competitors | B13: Product Targeting | C13: Face Care | D13: 300 | E13: Enabled | G13: Compete on rival product pages
A14: SP | Manual | Lips & Eyes | Exact | B14: Manual | C14: Face Care | D14: 700 | E14: Enabled | G14: Scale proven terms
A15: SP | Manual | Masks & Gels | Broad | B15: Manual | C15: Face Care | D15: 100 | E15: Paused | F15: 46283 | G15: Explore variations
A16: SP | Brand Defence | Exact | B16: Manual | C16: Brand | D16: 450 | E16: Enabled | G16: Protect brand searches

Sheet Seller_Notes
A1: Seller_Notes — message from the seller (Auralis Naturals)
A3: Hi team, thanks for taking this on. Here is the export for September. I want to grow, but profit matters more to me than sales.
A4: My question: my ACOS feels worse towards the end of the month. Is that true, and why?
A5: Please tell me where I am wasting money, what is working, and what you would change first.
A6: Reporting period: 1-28 September 2026. Week 1 = 1-7 Sep, Week 2 = 8-14 Sep, Week 3 = 15-21 Sep, Week 4 = 22-28 Sep.
A8: Rules for the Action_List
A9: Rule | B9: Name | C9: Condition (per campaign + search term, whole period, after cleaning) | D9: Action | E9: Note
A10: R4 | B10: Competitor brand terms | C10: Any search term that contains a competitor brand name (list below) and has spend of ₹100 or more in a campaign. | D10: Negate (add as negative keyword) | E10: Check this rule FIRST. A term caught by R4 should not be counted again under R1-R3.
A11: R1 | B11: Wasted spend | C11: A search term in a campaign with 40 or more clicks and 0 orders over the whole period. | D11: Pause / negate | E11: Saving = spend on that term in the period.
A12: R2 | B12: Under-bid winners | C12: 4 or more orders and ACOS below half of the product's break-even ACOS. | D12: Increase bid by 15% | E12: Estimate the gain only if you can justify it; otherwise leave blank.
A13: R3 | B13: Over-paying | C13: 4 or more orders and ACOS above the product's break-even ACOS. | D13: Reduce bid by 20% | E13: Leave saving blank or estimate with a stated assumption.
A15: Exceptions
A16: 1. Do not recommend any action for the campaign 'SP | Brand Defence | Exact'. I protect my own brand name and want it left alone.
A17: 2. Do not recommend actions for campaigns that are Paused (see Campaign_List).
A18: 3. Search terms are not case sensitive: treat 'Vitamin C Serum' and 'vitamin c serum' as the same term.
A19: 4. Break-even ACOS = (Selling Price - Product Cost - Amazon Fees) / Selling Price, from Product_Master.
A21: Competitor brand names
A22: Dermavault, Glowkind, Pureroots, Botanica Nine, Skinlore, Veluna, Mistral Herbals
A24: Data note: the export contains rows from two columns the tool pre-calculated (CTR, ACOS, ROAS, CVR). I cannot say they are all correct.

Sheet Cleaning_Log
A1: Cleaning_Log
A2: Fill in the yellow cells. One row per issue. Delete the example row.
A4: # | B4: Issue found | C4: Column / where | D4: Approx. rows affected | E4: What I did | F4: Why / assumption
A5: 1 | B5: Completely blank rows | C5: clean_data | D5: 4 | E5: deleted rows with no data in any column | F5: Removed entirely blank rows because they contain no useful information and can interfere with data filtering and analysis
A6: 2 | B6: Duplicate rows | C6: clean _data | D6: 37 | E6: used remove duplicates with all selected | F6: Retained the first occurrence of each identical row
A7: 3 | B7: Inconsistent date formats | C7: clean _data | D7: all | E7: Converted dates using Text to Columns with DMY format | F7: To ensure Excel recognizes dates correctly for weekly analysis.
A8: 4 | B8: total row named row found | C8: clean _data | D8: 1 | E8: removed it | F8: To prevent summary figures from being counted again in the analysis.
A9: 5 | B9: Inconsistent Match Type labels and extra spaces | C9: clean _data (Column H) | D9: all | E9: Used TRIM and UPPER to standardize text, then removed the MATCH suffix where applicable | F9: To ensure equivalent match types use consistent tabels and can be analysed acurately using pivot tables
A10: 6 | B10: Inconsistent SKU capitalization and extra spaces | C10: clean_data (Column J) | D10: all | E10: Used TRIM and UPPER, then pasted the cleaned values into column J | F10: To ensure the same product SKU is represented consistently, avoiding incorrect product-level grouping and lookup mismatches.
A11: 7 | B11: Inconsistent currency labels | C11: clean_data (Column X) | D11: all | E11: Standardized currency labels to INR | F11: The dataset represents Indian rupees, so equivalent currency labels were standardized to avoid inconsistent grouping.
A12: 8 | B12: Currency symbols and text-formatted Spend values | C12: clean_data(Column P) | D12: all | E12: Removed currency symbols and commas and converted values to numbers | F12: To ensure Spend values can be summed and used in advertising calculations while preserving negative refund amounts.
A13: 9 | B13: Missing Campaign Name | C13: Clean_data(Column B) | D13: 5 | E13: Identified and retained five records with blank campaign names for investigation | F13: The records contain useful advertising metrics. Deleting them would lose valid data, and campaign names cannot be reliably inferred from the Ad Group alone.
A14: 10 | B14: Inconsistent Customer Search Term capitalization and extra spaces | C14: Clean_data(Column I) | D14: all | E14: Used LOWER and TRIM to standardize capitalization and remove extra spaces, then pasted cleaned values into column I | F14: To ensure identical search terms are grouped consistently during search-term analysis.
A15: 11 | B15: Inconsistent Targeting Capitalization and extra spaces | C15: Clean Data ( Column G) | D15: all | E15: Used LOWER and TRIM to standardize capitalization and remove extra spaces, then pasted cleaned values into column G | F15: To improve consistency while preserving distinct targeting values and ASINs.
A16: 12 | B16: Impressions stored as text | C16: Clean Data ( Column L) | D16: 60 | E16: Converted text-formatted impression values into numbers | F16: To ensure impressions can be summed and used accurately in advertising performance calculations.
A17: 13 | B17: Inconsistent Region labels | C17: Clean_data( Column Y) | D17: 41 | E17: Standardized IN to India using Find and Replace, with Match entire cell contents enabled. | F17: Consistent region labels are required for accurate grouping and analysis.
A18: 14 | B18: Missing Product SKUs | C18: Clean data(column J) | D18: 6 | E18: Identified and retained six records with blank Product SKU values. Product lookup fields and Break-even ACOS remain blank, and Performance Status is set to Cost missing. | F18: Therecords contain useful advertising metrics, but the correct SKU cannot be confirmed from the available fields. Guessing values could lead to inaccurate product-level profitability analysis.
A19: 15 | B19: Missing Customer Search Term | C19: Clean data (column I) | D19: 6 | E19: Identified and retained six records with blank Customer Search Term values for investigation. | F19: These records contain useful advertising data. For AUTO targeting, a missing customer search term may require investigation; for other targeting types, the source data should be checked before assigning a value.
A20: 16 | B20: CTR greater than 100% | C20: Clean data (column N) | D20: 6 | E20: Identified six records where clicks exceed impressions. Retained the original values and flagged them for investigation. | F20: CTR is calculated as Clicks ÷ Impressions. The source values are inconsistent, and the correct values cannot be determined without verification.
A21: 17 | B21: Incorrect ACOS value | C21: Clean data (Column T) | D21: 1 | E21: Identified a mismatch between the reported ACOS of 480.00% and the value calculated from Spend and Sales (4.83%). Flagged the record for recalculation. | F21: ACOS is calculated as Spend ÷ Sales .The original value will be replaced by a formula during the metric-calculation stage.
A22: 18 | B22: Three dates had an incorrect year | C22: Clean data(column A) | D22: 3 | E22: Cross-checked against the original report and corrected the year to 2026 | F22: The reporting period is 1–28 September 2026
A23: 19 | B23: Paused campaign with post-pause reporting dates | C23: clean_data — Campaign Name, Campaign Status, Date | E23: Identified nine records dated 22–27 September 2026 for SP | Manual | Masks & Gels | Broad, which is marked Paused. Cross-checked Campaign_List, confirming a pause date of 18 September 2026. Retained the records pending clarification | F23: The records contain ₹598.44 in spend and zero reported sales. Their reporting dates are later than the recorded pause date, but the available data does not establish when the advertising activity occurred. The records have therefore been retained rather than deleted
A24: 20 | B24: Calculated metrics and lookup columns | C24: Clean_Data columns N,O,T,U,V,AA,AB,AC,AD:AG | E24: Replaced pre-filled metrics with formulas; used VLOOKUP against Product_lookup for compatibility; status prioritizes negative spend as Review and uses strict ACOS < break-even for Profitable. | F24: Profit is unavailable where SKU economics are missing; no costs were guessed.

Sheet Summary
A1: Summary
A2: Write your note (maximum 150 words) in cell A4. Then, in cell A8, list anything you were unsure about.
A3: Note to the seller:
A4: ACOS worsened at the end of September: it rose from 29.74% in Week 3 to 40.01% in Week 4. Week 4 spend increased to ₹43,970.92 while attributed sales fell to ₹109,907 and orders fell to 204; conversion rate also declined. Overall, the report shows ₹162,371.65 spend against ₹493,863 sales (32.88% ACOS; 3.04 ROAS). The first priority is to stop avoidable spend: review high-click, zero-order search terms and irrelevant searches, then apply the seller's R4 competitor-term rule first. Scale terms that meet R2 and reduce bids on R3 terms with at least four orders but ACOS above break-even. Exact-match traffic has the strongest overall return among match types, while product targeting is weakest. Profit totals are partial where SKU economics are missing, so fill the product-master gap before using those rows for profitability decisions.
A7: What I was unsure about / assumptions:
A8: Assumptions / uncertainties: 56 rows have blank SKU or SKN-024, which is absent from Product_Master; profit after ads is excluded for those rows rather than guessed. The export includes 90 rows for SP | Manual | Masks & Gels | Broad even though Campaign_List says it was paused on 18 Sep; retained in historical analysis but excluded from recommendations. Week definitions follow Seller_Notes. Bid changes are recommendations only; savings/gains are not guaranteed.

Sheet campaign-level PivotTable
A3: Row Labels | B3: Total Orders | C3: Total Units | D3: Impressions | E3: Total Sales (₹) | F3: Total Clicks | G3: Total AD Spend (₹) | H3: Campaign ACOS | I3: Campaign ROAS | J3: Profit after ads (₹)
A4: SP | Auto | Body & Hair | B4: 86 | C4: 91 | D4: 222466 | E4: 37629 | F4: 1994 | G4: 15368.21 | H4: =IF(E4=0,"",G4/E4) -> 0.40841399 | I4: =IF(G4=0,"",E4/G4) -> 2.448496 | J4: -3765.21
A5: SP | Auto | Face Care | B5: 85 | C5: 93 | D5: 278645 | E5: 41257 | F5: 2462 | G5: 20601.43 | H5: =IF(E5=0,"",G5/E5) -> 0.49934387 | I5: =IF(G5=0,"",E5/G5) -> 2.002628 | J5: -6311.43
A6: SP | Brand Defence | Exact | B6: 132 | C6: 148 | D6: 61027 | E6: 105902 | F6: 1310 | G6: 9259.88 | H6: =IF(E6=0,"",G6/E6) -> 0.087438198 | I6: =IF(G6=0,"",E6/G6) -> 11.436649 | J6: 18190.28
A7: SP | Manual | Body Care | Exact | B7: 134 | C7: 144 | D7: 258805 | E7: 46206 | F7: 2041 | G7: 16976.15 | H7: =IF(E7=0,"",G7/E7) -> 0.36740142 | I7: =IF(G7=0,"",E7/G7) -> 2.7218186 | J7: -3972.65
A8: SP | Manual | Face Serums | Broad | B8: 60 | C8: 66 | D8: 129859 | E8: 40884 | F8: 1044 | G8: 12651.35 | H8: =IF(E8=0,"",G8/E8) -> 0.30944502 | I8: =IF(G8=0,"",E8/G8) -> 3.2315919 | J8: 3941.65
A9: SP | Manual | Face Serums | Exact | B9: 121 | C9: 134 | D9: 231533 | E9: 88116 | F9: 2140 | G9: 32417.17 | H9: =IF(E9=0,"",G9/E9) -> 0.36789198 | I9: =IF(G9=0,"",E9/G9) -> 2.7181892 | J9: 4401.07
A10: SP | Manual | Hair Care | Phrase | B10: 40 | C10: 42 | D10: 134137 | E10: 19248 | F10: 1094 | G10: 10362.29 | H10: =IF(E10=0,"",G10/E10) -> 0.53835671 | I10: =IF(G10=0,"",E10/G10) -> 1.8575045 | J10: -3816.29
A11: SP | Manual | Lips & Eyes | Exact | B11: 150 | C11: 169 | D11: 207873 | E11: 53031 | F11: 1791 | G11: 14632.23 | H11: =IF(E11=0,"",G11/E11) -> 0.27591843 | I11: =IF(G11=0,"",E11/G11) -> 3.6242596 | J11: 1564.77
A12: SP | Manual | Masks & Gels | Broad | B12: 14 | C12: 15 | D12: 63997 | E12: 4905 | F12: 426 | G12: 2983.76 | H12: =IF(E12=0,"",G12/E12) -> 0.60830989 | I12: =IF(G12=0,"",E12/G12) -> 1.643899 | J12: -1636.76
A13: SP | Manual | Skincare Essentials | Broad | B13: 91 | C13: 93 | D13: 2685397 | E13: 31337 | F13: 1862 | G13: 12259.85 | H13: =IF(E13=0,"",G13/E13) -> 0.39122603 | I13: =IF(G13=0,"",E13/G13) -> 2.5560672 | J13: -3421.19
A14: SP | Manual | Sunscreen | Phrase | B14: 35 | C14: 38 | D14: 99424 | E14: 19162 | F14: 805 | G14: 8723.67 | H14: =IF(E14=0,"",G14/E14) -> 0.45525885 | I14: =IF(G14=0,"",E14/G14) -> 2.1965526 | J14: -1707.67
A15: SP | Product Targeting | Competitors | B15: 10 | C15: 10 | D15: 189188 | E15: 4790 | F15: 875 | G15: 6016.81 | H15: =IF(E15=0,"",G15/E15) -> 1.256119 | I15: =IF(G15=0,"",E15/G15) -> 0.79610292 | J15: -4273.81
A16: (blank) | B16: 3 | C16: 4 | D16: 2625 | E16: 1396 | F16: 15 | G16: 118.85 | H16: =IF(E16=0,"",G16/E16) -> 0.085136103 | I16: =IF(G16=0,"",E16/G16) -> 11.745898
A17: Grand Total | B17: 961 | C17: 1047 | D17: 4564976 | E17: 493863 | F17: 17859 | G17: 162371.65 | H17: =IF(E17=0,"",G17/E17) -> 0.32877873 | I17: =IF(G17=0,"",E17/G17) -> 3.0415593 | J17: -489.09

Sheet Match-Type Analysis PivotTable
A3: Row Labels | B3: Sum of 7 Day Total Units | C3: Sum of 7 Day Total Orders | D3: Sum of Impressions | E3: Sum of 7 Day Total Sales (₹) | F3: Sum of Clicks | G3: Sum of Spend (₹) | H3: Match_Type_ACOS | I3: Match Type ROAS | J3: Profit after ads (₹)
A4: AUTO | B4: 184 | C4: 171 | D4: 501253 | E4: 78886 | F4: 4456 | G4: 35969.64 | H4: =IF(E4=0,"",G4/E4) -> 0.45596988 | I4: =IF(G4=0,"",E4/G4) -> 2.1931273 | J4: -10076.64
A5: BROAD | B5: 174 | C5: 165 | D5: 2879253 | E5: 77126 | F5: 3332 | G5: 27894.96 | H5: =IF(E5=0,"",G5/E5) -> 0.36168037 | I5: =IF(G5=0,"",E5/G5) -> 2.7648722 | J5: -1116.3
A6: EXACT | B6: 599 | C6: 540 | D6: 761721 | E6: 294651 | F6: 7297 | G6: 73404.28 | H6: =IF(E6=0,"",G6/E6) -> 0.24912279 | I6: =IF(G6=0,"",E6/G6) -> 4.0140847 | J6: 20501.62
A7: PHRASE | B7: 80 | C7: 75 | D7: 233561 | E7: 38410 | F7: 1899 | G7: 19085.96 | H7: =IF(E7=0,"",G7/E7) -> 0.49690081 | I7: =IF(G7=0,"",E7/G7) -> 2.0124741 | J7: -5523.96
A8: PRODUCT | B8: 10 | C8: 10 | D8: 189188 | E8: 4790 | F8: 875 | G8: 6016.81 | H8: =IF(E8=0,"",G8/E8) -> 1.256119 | I8: =IF(G8=0,"",E8/G8) -> 0.79610292 | J8: -4273.81
A9: Grand Total | B9: 1047 | C9: 961 | D9: 4564976 | E9: 493863 | F9: 17859 | G9: 162371.65 | H9: =IF(E9=0,"",G9/E9) -> 0.32877873 | I9: =IF(G9=0,"",E9/G9) -> 3.0415593 | J9: -489.09

Sheet Placement Analysis PivotTable
A3: Row Labels | B3: Sum of 7 Day Total Units | C3: Sum of Impressions | D3: Sum of 7 Day Total Orders | E3: Sum of 7 Day Total Sales (₹) | F3: Sum of Spend (₹) | G3: Sum of Clicks | H3: Placement ACOS | I3: Placement ROAS | J3: Profit after ads (₹)
A4: Product Pages | B4: 223 | C4: 666850 | D4: 207 | E4: 97437 | F4: 34993.87 | G4: 4692 | H4: =IF(E4=0,"",F4/E4) -> 0.35914355 | I4: =IF(F4=0,"",E4/F4) -> 2.784402 | J4: -3055.48
A5: Rest of Search | B5: 374 | C5: 1005042 | D5: 341 | E5: 180536 | F5: 56866.21 | G5: 6890 | H5: =IF(E5=0,"",F5/E5) -> 0.31498543 | I5: =IF(F5=0,"",E5/F5) -> 3.17475 | J5: 1287.92
A6: Top of Search | B6: 450 | C6: 2893084 | D6: 413 | E6: 215890 | F6: 70511.57 | G6: 6277 | H6: =IF(E6=0,"",F6/E6) -> 0.32660878 | I6: =IF(F6=0,"",E6/F6) -> 3.061767 | J6: 1278.47
A7: Grand Total | B7: 1047 | C7: 4564976 | D7: 961 | E7: 493863 | F7: 162371.65 | G7: 17859 | H7: =IF(E7=0,"",F7/E7) -> 0.32877873 | I7: =IF(F7=0,"",E7/F7) -> 3.0415593 | J7: -489.09

Sheet Search_Term_Analysis
A1: Row Labels | B1: Sum of Impressions | C1: Sum of 7 Day Total Units | D1: Sum of 7 Day Total Orders | E1: Sum of 7 Day Total Sales (₹) | F1: Sum of Clicks | G1: Sum of Spend (₹) | H1: Search Term ACOS | I1: Action Check
A2: body lotion | B2: 45626 | C2: 20 | D2: 18 | E2: 8980 | F2: 527 | G2: 6390.5 | H2: =IF(E2=0,"",G2/E2) -> 0.71163697 | I2: =IF(AND(E2=0,G2>0),"Review","")
A3: niacinamide serum | B3: 54128 | C3: 0 | D3: 0 | E3: 0 | F3: 556 | G3: 5911.46 | H3: =IF(E3=0,"",G3/E3) | I3: =IF(AND(E3=0,G3>0),"Review","") -> Review
A4: hyaluronic acid serum | B4: 45109 | C4: 38 | D4: 35 | E4: 24662 | F4: 394 | G4: 5321.04 | H4: =IF(E4=0,"",G4/E4) -> 0.21575866 | I4: =IF(AND(E4=0,G4>0),"Review","")
A5: vitamin c serum | B5: 35988 | C5: 19 | D5: 17 | E5: 11381 | F5: 378 | G5: 5286.13 | H5: =IF(E5=0,"",G5/E5) -> 0.46446973 | I5: =IF(AND(E5=0,G5>0),"Review","")
A6: retinol night cream | B6: 37906 | C6: 15 | D6: 13 | E6: 11985 | F6: 313 | G6: 4913.2 | H6: =IF(E6=0,"",G6/E6) -> 0.40994577 | I6: =IF(AND(E6=0,G6>0),"Review","")
A7: hyaluronic serum | B7: 24437 | C7: 45 | D7: 40 | E7: 29205 | F7: 298 | G7: 4851.51 | H7: =IF(E7=0,"",G7/E7) -> 0.16611916 | I7: =IF(AND(E7=0,G7>0),"Review","")
A8: gel moisturizer | B8: 48630 | C8: 19 | D8: 19 | E8: 7581 | F8: 458 | G8: 4127.99 | H8: =IF(E8=0,"",G8/E8) -> 0.54451787 | I8: =IF(AND(E8=0,G8>0),"Review","")
A9: lip sleeping mask | B9: 40604 | C9: 4 | D9: 3 | E9: 1196 | F9: 402 | G9: 3018.02 | H9: =IF(E9=0,"",G9/E9) -> 2.5234281 | I9: =IF(AND(E9=0,G9>0),"Review","")
A10: vit c face serum | B10: 21780 | C10: 12 | D10: 11 | E10: 7188 | F10: 268 | G10: 2864.44 | H10: =IF(E10=0,"",G10/E10) -> 0.39850306 | I10: =IF(AND(E10=0,G10>0),"Review","")
A11: retinol cream | B11: 15167 | C11: 1 | D11: 1 | E11: 799 | F11: 165 | G11: 2794.44 | H11: =IF(E11=0,"",G11/E11) -> 3.4974218 | I11: =IF(AND(E11=0,G11>0),"Review","")
A12: sunscreen | B12: 15301 | C12: 2 | D12: 2 | E12: 898 | F12: 208 | G12: 2476.44 | H12: =IF(E12=0,"",G12/E12) -> 2.7577283 | I12: =IF(AND(E12=0,G12>0),"Review","")
A13: body wash | B13: 47088 | C13: 17 | D13: 16 | E13: 5933 | F13: 372 | G13: 2410.28 | H13: =IF(E13=0,"",G13/E13) -> 0.40624979 | I13: =IF(AND(E13=0,G13>0),"Review","")
... A72: spf 50 sunscreen for face | B72: 7536 | C72: 0 | D72: 0 | E72: 0 | F72: 60 | G72: 562.61 | H72: =IF(E72=0,"",G72/E72) | I72: =IF(AND(E72=0,G72>0),"Review","") -> Review
B73: 7493 | C73: 6 | D73: 6 | E73: 2494 | F73: 64 | G73: 562.15 | H73: =IF(E73=0,"",G73/E73) -> 0.22540096 | I73: =IF(AND(E73=0,G73>0),"Review","")
A74: auralis naturals kumkumadi oil | B74: 3245 | C74: 5 | D74: 3 | E74: 6495 | F74: 47 | G74: 558.08 | H74: =IF(E74=0,"",G74/E74) -> 0.085924557 | I74: =IF(AND(E74=0,G74>0),"Review","")
A75: oil free moisturizer | B75: 9392 | C75: 9 | D75: 8 | E75: 3591 | F75: 68 | G75: 554.97 | H75: =IF(E75=0,"",G75/E75) -> 0.1545447 | I75: =IF(AND(E75=0,G75>0),"Review","")
A76: hyaluronic serum for sensitive skin | B76: 5305 | C76: 0 | D76: 0 | E76: 0 | F76: 31 | G76: 542.44 | H76: =IF(E76=0,"",G76/E76) | I76: =IF(AND(E76=0,G76>0),"Review","") -> Review
A77: night cream for face for dry skin | B77: 3317 | C77: 2 | D77: 2 | E77: 1598 | F77: 28 | G77: 539.18 | H77: =IF(E77=0,"",G77/E77) -> 0.33740926 | I77: =IF(AND(E77=0,G77>0),"Review","")
A78: spf 50 sunscreen for face price | B78: 2733 | C78: 6 | D78: 4 | E78: 2694 | F78: 88 | G78: 538.99 | H78: =IF(E78=0,"",G78/E78) -> 0.20007053 | I78: =IF(AND(E78=0,G78>0),"Review","")
A79: auralis sunscreen | B79: 4258 | C79: 7 | D79: 7 | E79: 3143 | F79: 118 | G79: 537.14 | H79: =IF(E79=0,"",G79/E79) -> 0.17090041 | I79: =IF(AND(E79=0,G79>0),"Review","")
A80: retinol cream combo | B80: 3154 | C80: 0 | D80: 0 | E80: 0 | F80: 38 | G80: 535.04 | H80: =IF(E80=0,"",G80/E80) | I80: =IF(AND(E80=0,G80>0),"Review","") -> Review
A81: face cream for dogs | B81: 9573 | C81: 0 | D81: 0 | E81: 0 | F81: 61 | G81: 521.81 | H81: =IF(E81=0,"",G81/E81) | I81: =IF(AND(E81=0,G81>0),"Review","") -> Review
A82: gel moisturizer dermatologist tested | B82: 4843 | C82: 2 | D82: 2 | E82: 798 | F82: 58 | G82: 508.69 | H82: =IF(E82=0,"",G82/E82) -> 0.63745614 | I82: =IF(AND(E82=0,G82>0),"Review","")
A83: niacinamide serum for teenagers | B83: 7368 | C83: 0 | D83: 0 | E83: 0 | F83: 41 | G83: 498.45 | H83: =IF(E83=0,"",G83/E83) | I83: =IF(AND(E83=0,G83>0),"Review","") -> Review
A84: b0q7ldyo0l | B84: 11524 | C84: 0 | D84: 0 | E84: 0 | F84: 66 | G84: 495.85 | H84: =IF(E84=0,"",G84/E84) | I84: =IF(AND(E84=0,G84>0),"Review","") -> Review
A85: dark circles cream for beginners | B85: 4335 | C85: 0 | D85: 0 | E85: 0 | F85: 46 | G85: 485.88 | H85: =IF(E85=0,"",G85/E85) | I85: =IF(AND(E85=0,G85>0),"Review","") -> Review
... A530: Grand Total | B530: 4564976 | C530: 1047 | D530: 961 | E530: 493863 | F530: 17859 | G530: 162371.65 | H530: =IF(E530=0,"",G530/E530) -> 0.32877873 | I530: =IF(AND(E530=0,G530>0),"Review","")

Sheet Clean_Data
A1: Date | B1: Campaign Name | C1: Portfolio | D1: Campaign Status | E1: Ad Group | F1: Ad Format | G1: Targeting | H1: Match Type | I1: Customer Search Term | J1: Product SKU | K1: Placement | L1: Impressions | M1: Clicks | N1: CTR | O1: CPC (₹) | P1: Spend (₹) | Q1: 7 Day Total Sales (₹) | R1: 7 Day Total Orders | S1: 7 Day Total Units | T1: ACOS | U1: ROAS | V1: CVR | W1: Bid (₹) | X1: Currency | Y1: Region | Z1: Notes | AA1: Week No. | AB1: Profit after ads (₹) | AC1: Row Status | AD1: Selling_Price | AE1: Product_cost | AF1: Amazon_fees | AG1: Break-even ACOS
A2: 46266 | B2: SP | Auto | Face Care | C2: Face Care | D2: Enabled | E2: AG | Vitamin C Serum | F2: Sponsored Products | G2: close-match | H2: AUTO | I2: best face serum vitamin c | J2: SKN-001 | K2: Top of Search | L2: 125 | M2: 4 | N2: =IF(L2=0,"",M2/L2) -> 0.032 | O2: =IF(M2=0,"",P2/M2) -> 15.54 | P2: 62.16 | Q2: 0 | R2: 0 | S2: 0 | T2: =IF(Q2=0,"",P2/Q2) | U2: =IF(P2=0,"",Q2/P2) -> 0 | V2: =IF(M2=0,"",R2/M2) -> 0 | W2: 17.5 | X2: INR | Y2: India | AA2: =IF(OR(A2<DATE(2026,9,1),A2>DATE(2026,9,28)),"Check Date",INT((A2-DATE(2026,9,1))/7)+1) -> 1 | AB2: =IF(OR(AD2="",AE2="",AF2=""),"",S2*(AD2-AE2-AF2)-P2) -> -62.16 | AC2: =IF(P2<0,"Review",IF(OR(AD2="",AE2="",AF2=""),"Cost missing",IF(P2=0,"No Spend",IF(Q2=0,"No Sales",IF(P2/Q2<AG2,"Profitable","Losing"))))) -> No Sales | AD2: =IFERROR(VLOOKUP(J2,Product_lookup!$A:$G,5,FALSE),"") -> 599 | AE2: =IFERROR(VLOOKUP(J2,Product_lookup!$A:$G,6,FALSE),"") -> 216 | AF2: =IFERROR(VLOOKUP(J2,Product_lookup!$A:$G,7,FALSE),"") -> 144 | AG2: =IFERROR((AD2-AE2-AF2)/AD2,"") -> 0.39899833
A3: 46266 | B3: SP | Auto | Face Care | C3: Face Care | D3: Enabled | E3: AG | Niacinamide Serum | F3: Sponsored Products | G3: loose-match | H3: AUTO | I3: niacinamide serum with vitamin e | J3: SKN-002 | K3: Top of Search | L3: 300 | M3: 4 | N3: =IF(L3=0,"",M3/L3) -> 0.013333333 | O3: =IF(M3=0,"",P3/M3) -> 16.5 | P3: 66 | Q3: 0 | R3: 0 | S3: 0 | T3: =IF(Q3=0,"",P3/Q3) | U3: =IF(P3=0,"",Q3/P3) -> 0 | V3: =IF(M3=0,"",R3/M3) -> 0 | W3: 16.5 | X3: INR | Y3: India | AA3: =IF(OR(A3<DATE(2026,9,1),A3>DATE(2026,9,28)),"Check Date",INT((A3-DATE(2026,9,1))/7)+1) -> 1 | AB3: =IF(OR(AD3="",AE3="",AF3=""),"",S3*(AD3-AE3-AF3)-P3) -> -66 | AC3: =IF(P3<0,"Review",IF(OR(AD3="",AE3="",AF3=""),"Cost missing",IF(P3=0,"No Spend",IF(Q3=0,"No Sales",IF(P3/Q3<AG3,"Profitable","Losing"))))) -> No Sales | AD3: =IFERROR(VLOOKUP(J3,Product_lookup!$A:$G,5,FALSE),"") -> 549 | AE3: =IFERROR(VLOOKUP(J3,Product_lookup!$A:$G,6,FALSE),"") -> 192 | AF3: =IFERROR(VLOOKUP(J3,Product_lookup!$A:$G,7,FALSE),"") -> 139 | AG3: =IFERROR((AD3-AE3-AF3)/AD3,"") -> 0.39708561
A4: 46266 | B4: SP | Auto | Face Care | C4: Face Care | D4: Enabled | E4: AG | Niacinamide Serum | F4: Sponsored Products | G4: close-match | H4: AUTO | I4: organic niacinamide 10% serum | J4: SKN-002 | K4: Product Pages | L4: 201 | M4: 5 | N4: =IF(L4=0,"",M4/L4) -> 0.024875622 | O4: =IF(M4=0,"",P4/M4) -> 6.14 | P4: 30.7 | Q4: 0 | R4: 0 | S4: 0 | T4: =IF(Q4=0,"",P4/Q4) | U4: =IF(P4=0,"",Q4/P4) -> 0 | V4: =IF(M4=0,"",R4/M4) -> 0 | W4: 10.5 | X4: INR | Y4: India | AA4: =IF(OR(A4<DATE(2026,9,1),A4>DATE(2026,9,28)),"Check Date",INT((A4-DATE(2026,9,1))/7)+1) -> 1 | AB4: =IF(OR(AD4="",AE4="",AF4=""),"",S4*(AD4-AE4-AF4)-P4) -> -30.7 | AC4: =IF(P4<0,"Review",IF(OR(AD4="",AE4="",AF4=""),"Cost missing",IF(P4=0,"No Spend",IF(Q4=0,"No Sales",IF(P4/Q4<AG4,"Profitable","Losing"))))) -> No Sales | AD4: =IFERROR(VLOOKUP(J4,Product_lookup!$A:$G,5,FALSE),"") -> 549 | AE4: =IFERROR(VLOOKUP(J4,Product_lookup!$A:$G,6,FALSE),"") -> 192 | AF4: =IFERROR(VLOOKUP(J4,Product_lookup!$A:$G,7,FALSE),"") -> 139 | AG4: =IFERROR((AD4-AE4-AF4)/AD4,"") -> 0.39708561
A5: 46266 | B5: SP | Auto | Face Care | C5: Face Care | D5: Enabled | E5: AG | Niacinamide Serum | F5: Sponsored Products | G5: loose-match | H5: AUTO | I5: niacinamide 10% serum | J5: SKN-002 | K5: Rest of Search | L5: 808 | M5: 4 | N5: =IF(L5=0,"",M5/L5) -> 0.004950495 | O5: =IF(M5=0,"",P5/M5) -> 6.82 | P5: 27.28 | Q5: 0 | R5: 0 | S5: 0 | T5: =IF(Q5=0,"",P5/Q5) | U5: =IF(P5=0,"",Q5/P5) -> 0 | V5: =IF(M5=0,"",R5/M5) -> 0 | W5: 10 | X5: INR | Y5: India | AA5: =IF(OR(A5<DATE(2026,9,1),A5>DATE(2026,9,28)),"Check Date",INT((A5-DATE(2026,9,1))/7)+1) -> 1 | AB5: =IF(OR(AD5="",AE5="",AF5=""),"",S5*(AD5-AE5-AF5)-P5) -> -27.28 | AC5: =IF(P5<0,"Review",IF(OR(AD5="",AE5="",AF5=""),"Cost missing",IF(P5=0,"No Spend",IF(Q5=0,"No Sales",IF(P5/Q5<AG5,"Profitable","Losing"))))) -> No Sales | AD5: =IFERROR(VLOOKUP(J5,Product_lookup!$A:$G,5,FALSE),"") -> 549 | AE5: =IFERROR(VLOOKUP(J5,Product_lookup!$A:$G,6,FALSE),"") -> 192 | AF5: =IFERROR(VLOOKUP(J5,Product_lookup!$A:$G,7,FALSE),"") -> 139 | AG5: =IFERROR((AD5-AE5-AF5)/AD5,"") -> 0.39708561
A6: 46266 | B6: SP | Auto | Face Care | C6: Face Care | D6: Enabled | E6: AG | Gel Moisturizer | F6: Sponsored Products | G6: loose-match | H6: AUTO | I6: organic gel moisturizer | J6: SKN-005 | K6: Product Pages | L6: 216 | M6: 0 | N6: =IF(L6=0,"",M6/L6) -> 0 | O6: =IF(M6=0,"",P6/M6) | P6: 0 | Q6: 0 | R6: 0 | S6: 0 | T6: =IF(Q6=0,"",P6/Q6) | U6: =IF(P6=0,"",Q6/P6) | V6: =IF(M6=0,"",R6/M6) | W6: 12 | X6: INR | Y6: India | AA6: =IF(OR(A6<DATE(2026,9,1),A6>DATE(2026,9,28)),"Check Date",INT((A6-DATE(2026,9,1))/7)+1) -> 1 | AB6: =IF(OR(AD6="",AE6="",AF6=""),"",S6*(AD6-AE6-AF6)-P6) -> 0 | AC6: =IF(P6<0,"Review",IF(OR(AD6="",AE6="",AF6=""),"Cost missing",IF(P6=0,"No Spend",IF(Q6=0,"No Sales",IF(P6/Q6<AG6,"Profitable","Losing"))))) -> No Spend | AD6: =IFERROR(VLOOKUP(J6,Product_lookup!$A:$G,5,FALSE),"") -> 399 | AE6: =IFERROR(VLOOKUP(J6,Product_lookup!$A:$G,6,FALSE),"") -> 148 | AF6: =IFERROR(VLOOKUP(J6,Product_lookup!$A:$G,7,FALSE),"") -> 126 | AG6: =IFERROR((AD6-AE6-AF6)/AD6,"") -> 0.31328321
A7: 46266 | B7: SP | Auto | Face Care | C7: Face Care | D7: Enabled | E7: AG | Gel Moisturizer | F7: Sponsored Products | G7: close-match | H7: AUTO | I7: face moisturizer | J7: SKN-005 | K7: Rest of Search | L7: 1431 | M7: 17 | N7: =IF(L7=0,"",M7/L7) -> 0.011879804 | O7: =IF(M7=0,"",P7/M7) -> 6 | P7: 102 | Q7: 399 | R7: 1 | S7: 1 | T7: =IF(Q7=0,"",P7/Q7) -> 0.2556391 | U7: =IF(P7=0,"",Q7/P7) -> 3.9117647 | V7: =IF(M7=0,"",R7/M7) -> 0.058823529 | W7: 10.5 | X7: INR | Y7: India | AA7: =IF(OR(A7<DATE(2026,9,1),A7>DATE(2026,9,28)),"Check Date",INT((A7-DATE(2026,9,1))/7)+1) -> 1 | AB7: =IF(OR(AD7="",AE7="",AF7=""),"",S7*(AD7-AE7-AF7)-P7) -> 23 | AC7: =IF(P7<0,"Review",IF(OR(AD7="",AE7="",AF7=""),"Cost missing",IF(P7=0,"No Spend",IF(Q7=0,"No Sales",IF(P7/Q7<AG7,"Profitable","Losing"))))) -> Profitable | AD7: =IFERROR(VLOOKUP(J7,Product_lookup!$A:$G,5,FALSE),"") -> 399 | AE7: =IFERROR(VLOOKUP(J7,Product_lookup!$A:$G,6,FALSE),"") -> 148 | AF7: =IFERROR(VLOOKUP(J7,Product_lookup!$A:$G,7,FALSE),"") -> 126 | AG7: =IFERROR((AD7-AE7-AF7)/AD7,"") -> 0.31328321
A8: 46266 | B8: SP | Auto | Face Care | C8: Face Care | D8: Enabled | E8: AG | Gel Moisturizer | F8: Sponsored Products | G8: close-match | H8: AUTO | I8: gel moisturizer | J8: SKN-005 | K8: Top of Search | L8: 1449 | M8: 22 | N8: =IF(L8=0,"",M8/L8) -> 0.015182885 | O8: =IF(M8=0,"",P8/M8) -> 11.5 | P8: 253 | Q8: 1197 | R8: 3 | S8: 3 | T8: =IF(Q8=0,"",P8/Q8) -> 0.21136174 | U8: =IF(P8=0,"",Q8/P8) -> 4.7312253 | V8: =IF(M8=0,"",R8/M8) -> 0.13636364 | W8: 12 | X8: INR | Y8: India | AA8: =IF(OR(A8<DATE(2026,9,1),A8>DATE(2026,9,28)),"Check Date",INT((A8-DATE(2026,9,1))/7)+1) -> 1 | AB8: =IF(OR(AD8="",AE8="",AF8=""),"",S8*(AD8-AE8-AF8)-P8) -> 122 | AC8: =IF(P8<0,"Review",IF(OR(AD8="",AE8="",AF8=""),"Cost missing",IF(P8=0,"No Spend",IF(Q8=0,"No Sales",IF(P8/Q8<AG8,"Profitable","Losing"))))) -> Profitable | AD8: =IFERROR(VLOOKUP(J8,Product_lookup!$A:$G,5,FALSE),"") -> 399 | AE8: =IFERROR(VLOOKUP(J8,Product_lookup!$A:$G,6,FALSE),"") -> 148 | AF8: =IFERROR(VLOOKUP(J8,Product_lookup!$A:$G,7,FALSE),"") -> 126 | AG8: =IFERROR((AD8-AE8-AF8)/AD8,"") -> 0.31328321
A9: 46266 | B9: SP | Auto | Face Care | C9: Face Care | D9: Enabled | E9: AG | Sunscreen Spf 50 | F9: Sponsored Products | G9: close-match | H9: AUTO | I9: sunscreen spf 50 | J9: SKN-006 | K9: Product Pages | L9: 2603 | M9: 14 | N9: =IF(L9=0,"",M9/L9) -> 0.0053784095 | O9: =IF(M9=0,"",P9/M9) -> 7.67 | P9: 107.38 | Q9: 0 | R9: 0 | S9: 0 | T9: =IF(Q9=0,"",P9/Q9) | U9: =IF(P9=0,"",Q9/P9) -> 0 | V9: =IF(M9=0,"",R9/M9) -> 0 | W9: 12 | X9: INR | Y9: India | AA9: =IF(OR(A9<DATE(2026,9,1),A9>DATE(2026,9,28)),"Check Date",INT((A9-DATE(2026,9,1))/7)+1) -> 1 | AB9: =IF(OR(AD9="",AE9="",AF9=""),"",S9*(AD9-AE9-AF9)-P9) -> -107.38 | AC9: =IF(P9<0,"Review",IF(OR(AD9="",AE9="",AF9=""),"Cost missing",IF(P9=0,"No Spend",IF(Q9=0,"No Sales",IF(P9/Q9<AG9,"Profitable","Losing"))))) -> No Sales | AD9: =IFERROR(VLOOKUP(J9,Product_lookup!$A:$G,5,FALSE),"") -> 449 | AE9: =IFERROR(VLOOKUP(J9,Product_lookup!$A:$G,6,FALSE),"") -> 162 | AF9: =IFERROR(VLOOKUP(J9,Product_lookup!$A:$G,7,FALSE),"") -> 130 | AG9: =IFERROR((AD9-AE9-AF9)/AD9,"") -> 0.34966592
A10: 46266 | B10: SP | Auto | Face Care | C10: Face Care | D10: Enabled | E10: AG | Rose Water Toner | F10: Sponsored Products | G10: close-match | H10: AUTO | I10: rose water toner | J10: SKN-010 | K10: Top of Search | L10: 993 | M10: 3 | N10: =IF(L10=0,"",M10/L10) -> 0.003021148 | O10: =IF(M10=0,"",P10/M10) -> 7.49 | P10: 22.47 | Q10: 0 | R10: 0 | S10: 0 | T10: =IF(Q10=0,"",P10/Q10) | U10: =IF(P10=0,"",Q10/P10) -> 0 | V10: =IF(M10=0,"",R10/M10) -> 0 | W10: 8 | X10: INR | Y10: India | AA10: =IF(OR(A10<DATE(2026,9,1),A10>DATE(2026,9,28)),"Check Date",INT((A10-DATE(2026,9,1))/7)+1) -> 1 | AB10: =IF(OR(AD10="",AE10="",AF10=""),"",S10*(AD10-AE10-AF10)-P10) -> -22.47 | AC10: =IF(P10<0,"Review",IF(OR(AD10="",AE10="",AF10=""),"Cost missing",IF(P10=0,"No Spend",IF(Q10=0,"No Sales",IF(P10/Q10<AG10,"Profitable","Losing"))))) -> No Sales | AD10: =IFERROR(VLOOKUP(J10,Product_lookup!$A:$G,5,FALSE),"") -> 249 | AE10: =IFERROR(VLOOKUP(J10,Product_lookup!$A:$G,6,FALSE),"") -> 100 | AF10: =IFERROR(VLOOKUP(J10,Product_lookup!$A:$G,7,FALSE),"") -> 102 | AG10: =IFERROR((AD10-AE10-AF10)/AD10,"") -> 0.18875502
A11: 46266 | B11: SP | Auto | Face Care | C11: Face Care | D11: Enabled | E11: AG | Rose Water Toner | F11: Sponsored Products | G11: complements | H11: AUTO | I11: face cream for dogs | J11: SKN-010 | K11: Product Pages | L11: 233 | M11: 2 | N11: =IF(L11=0,"",M11/L11) -> 0.008583691 | O11: =IF(M11=0,"",P11/M11) -> 2.95 | P11: 5.9 | Q11: 0 | R11: 0 | S11: 0 | T11: =IF(Q11=0,"",P11/Q11) | U11: =IF(P11=0,"",Q11/P11) -> 0 | V11: =IF(M11=0,"",R11/M11) -> 0 | W11: 5.5 | X11: INR | Y11: India | AA11: =IF(OR(A11<DATE(2026,9,1),A11>DATE(2026,9,28)),"Check Date",INT((A11-DATE(2026,9,1))/7)+1) -> 1 | AB11: =IF(OR(AD11="",AE11="",AF11=""),"",S11*(AD11-AE11-AF11)-P11) -> -5.9 | AC11: =IF(P11<0,"Review",IF(OR(AD11="",AE11="",AF11=""),"Cost missing",IF(P11=0,"No Spend",IF(Q11=0,"No Sales",IF(P11/Q11<AG11,"Profitable","Losing"))))) -> No Sales | AD11: =IFERROR(VLOOKUP(J11,Product_lookup!$A:$G,5,FALSE),"") -> 249 | AE11: =IFERROR(VLOOKUP(J11,Product_lookup!$A:$G,6,FALSE),"") -> 100 | AF11: =IFERROR(VLOOKUP(J11,Product_lookup!$A:$G,7,FALSE),"") -> 102 | AG11: =IFERROR((AD11-AE11-AF11)/AD11,"") -> 0.18875502
A12: 46266 | B12: SP | Auto | Face Care | C12: Face Care | D12: Enabled | E12: AG | Rose Water Toner | F12: Sponsored Products | G12: close-match | H12: AUTO | I12: face toner price | J12: SKN-010 | K12: Top of Search | L12: 247 | M12: 1 | N12: =IF(L12=0,"",M12/L12) -> 0.004048583 | O12: =IF(M12=0,"",P12/M12) -> 6 | P12: 6 | Q12: 0 | R12: 0 | S12: 0 | T12: =IF(Q12=0,"",P12/Q12) | U12: =IF(P12=0,"",Q12/P12) -> 0 | V12: =IF(M12=0,"",R12/M12) -> 0 | W12: 6 | X12: INR | Y12: India | AA12: =IF(OR(A12<DATE(2026,9,1),A12>DATE(2026,9,28)),"Check Date",INT((A12-DATE(2026,9,1))/7)+1) -> 1 | AB12: =IF(OR(AD12="",AE12="",AF12=""),"",S12*(AD12-AE12-AF12)-P12) -> -6 | AC12: =IF(P12<0,"Review",IF(OR(AD12="",AE12="",AF12=""),"Cost missing",IF(P12=0,"No Spend",IF(Q12=0,"No Sales",IF(P12/Q12<AG12,"Profitable","Losing"))))) -> No Sales | AD12: =IFERROR(VLOOKUP(J12,Product_lookup!$A:$G,5,FALSE),"") -> 249 | AE12: =IFERROR(VLOOKUP(J12,Product_lookup!$A:$G,6,FALSE),"") -> 100 | AF12: =IFERROR(VLOOKUP(J12,Product_lookup!$A:$G,7,FALSE),"") -> 102 | AG12: =IFERROR((AD12-AE12-AF12)/AD12,"") -> 0.18875502
A13: 46266 | B13: SP | Auto | Body & Hair | C13: Body & Hair | D13: Enabled | E13: AG | Body Lotion | F13: Sponsored Products | G13: close-match | H13: AUTO | I13: body lotion for dry skin | J13: SKN-017 | K13: Rest of Search | L13: 1128 | M13: 5 | N13: =IF(L13=0,"",M13/L13) -> 0.0044326241 | O13: =IF(M13=0,"",P13/M13) -> 7.2 | P13: 36 | Q13: 0 | R13: 0 | S13: 0 | T13: =IF(Q13=0,"",P13/Q13) | U13: =IF(P13=0,"",Q13/P13) -> 0 | V13: =IF(M13=0,"",R13/M13) -> 0 | W13: 12 | X13: INR | Y13: India | Z13: seller wants to monitor | AA13: =IF(OR(A13<DATE(2026,9,1),A13>DATE(2026,9,28)),"Check Date",INT((A13-DATE(2026,9,1))/7)+1) -> 1 | AB13: =IF(OR(AD13="",AE13="",AF13=""),"",S13*(AD13-AE13-AF13)-P13) -> -36 | AC13: =IF(P13<0,"Review",IF(OR(AD13="",AE13="",AF13=""),"Cost missing",IF(P13=0,"No Spend",IF(Q13=0,"No Sales",IF(P13/Q13<AG13,"Profitable","Losing"))))) -> No Sales | AD13: =IFERROR(VLOOKUP(J13,Product_lookup!$A:$G,5,FALSE),"") -> 449 | AE13: =IFERROR(VLOOKUP(J13,Product_lookup!$A:$G,6,FALSE),"") -> 166 | AF13: =IFERROR(VLOOKUP(J13,Product_lookup!$A:$G,7,FALSE),"") -> 140 | AG13: =IFERROR((AD13-AE13-AF13)/AD13,"") -> 0.31848552
A14: 46266 | B14: SP | Auto | Body & Hair | C14: Body & Hair | D14: Enabled | E14: AG | Body Lotion | F14: Sponsored Products | G14: substitutes | H14: AUTO | I14: veluna shea body lotion | J14: SKN-017 | K14: Top of Search | L14: 115 | M14: 1 | N14: =IF(L14=0,"",M14/L14) -> 0.0086956522 | O14: =IF(M14=0,"",P14/M14) -> 14 | P14: 14 | Q14: 0 | R14: 0 | S14: 0 | T14: =IF(Q14=0,"",P14/Q14) | U14: =IF(P14=0,"",Q14/P14) -> 0 | V14: =IF(M14=0,"",R14/M14) -> 0 | W14: 14 | X14: INR | Y14: India | AA14: =IF(OR(A14<DATE(2026,9,1),A14>DATE(2026,9,28)),"Check Date",INT((A14-DATE(2026,9,1))/7)+1) -> 1 | AB14: =IF(OR(AD14="",AE14="",AF14=""),"",S14*(AD14-AE14-AF14)-P14) -> -14 | AC14: =IF(P14<0,"Review",IF(OR(AD14="",AE14="",AF14=""),"Cost missing",IF(P14=0,"No Spend",IF(Q14=0,"No Sales",IF(P14/Q14<AG14,"Profitable","Losing"))))) -> No Sales | AD14: =IFERROR(VLOOKUP(J14,Product_lookup!$A:$G,5,FALSE),"") -> 449 | AE14: =IFERROR(VLOOKUP(J14,Product_lookup!$A:$G,6,FALSE),"") -> 166 | AF14: =IFERROR(VLOOKUP(J14,Product_lookup!$A:$G,7,FALSE),"") -> 140 | AG14: =IFERROR((AD14-AE14-AF14)/AD14,"") -> 0.31848552
